<?xml version="1.0" encoding="utf-8"?>
<mujoco model="XMLModel">
	<statistic center="0 0 1" extent="2"/>
	<option timestep="0.00555"/>
	<default>
		<motor ctrllimited="true" ctrlrange="-1 1"/>
		<default class="body">
			<geom condim="1" friction="1.0 0.05 0.05" type="capsule" solimp="0.9 0.99 0.003" solref="0.015 1"/>
			<joint armature="0.007" damping="0.1" limited="true" stiffness="5" type="hinge" solimplimit="0 0.99 0.01"/>
			<site group="3" size="0.04"/>
			<default class="force-torque">
				<site rgba="1 0 0 1" size="0.01 0.01 0.02" type="box"/>
			</default>
			<default class="touch">
				<site rgba="0 0 1 0.3" type="capsule"/>
			</default>
		</default>
	</default>
	<asset>
		<texture builtin="gradient" height="100" rgb1="0.8 0.8 0.8" rgb2="0.8 0.8 0.8" type="skybox" width="100" />
		<texture builtin="flat" height="1278" mark="cross" markrgb="1 1 1" name="texgeom" random="0.01" rgb1="0.8 0.6 0.4" rgb2="0.8 0.6 0.4" type="cube" width="127" />
		<texture builtin="checker" height="100" name="texplane" random="0.01" rgb1="0.8 0.8 0.8" rgb2="0.8 0.8 0.8" type="2d" width="100" />
		<material name="MatPlane" reflectance="0.5" shininess="1" specular="1" texrepeat="60 60" texture="texplane" />
		<material name="geom" texture="texgeom" texuniform="true" />
	</asset>
	<worldbody>
		<light cutoff="100" diffuse="1 1 1" dir="-0 0 -1.3" directional="true" exponent="1" pos="1 0 1.3" specular=".1 .1 .1" />
		<camera name="track_3" mode="fixed" pos="6.5 0 11.5" xyaxes="1 0 0 0 1 0" />
		<camera name="staris_camera" mode="fixed" pos="-1 -6 2.6" xyaxes="0.88 -0.5 0 0.1 0.1 0.99" />
		<geom condim="3" friction="1 .1 .1" material="MatPlane" name="flatfloor" pos="0 0 0" rgba="0.8 0.9 0.8 1" size="20 20 2" type="plane" />
		<body childclass="body" name="pelvis" pos="0 0 1">
			<freejoint name="root"/>
			<site class="force-torque" name="root"/>
			<site class="touch" name="pelvis" pos="0 0 0.07" size="0.091" type="sphere"/>
			<site class="touch" name="upper_waist" pos="0 0 0.205" size="0.071" type="sphere"/>

			<!-- <body name="SRL_root" pos="-0.07 -0.3 0.05" quat="-0.70711 0.0 0.70711 0.0">
				<geom density="2500" name="SRL_geom_root" pos="0 0 0" size="0.02 0.095 0.095" type="box"/>
				<body name="SRL_right_leg1" pos="0.02 0.0475 0" quat="1.0 0.0 0.0 0.0">
					<geom density="2500" fromto="0 0 0 0.3 0 0" name="SRL_geom_right_leg1" size="0.026026" type="capsule"/>
					<joint armature="0.02" axis="0 0 1" damping="30" name="SRL_joint_right_hipjoint_z" pos="0 0 0" range="0 40" stiffness="300"/>
					<joint armature="0.02" axis="0 1 0" damping="30" name="SRL_joint_right_hipjoint_y" pos="0 0 0" range="-5 70" stiffness="300"/>
					<body name="SRL_right_leg2" pos="0.3 0 0" quat="0.70711 0.0 0.70711 0.0">
						<geom density="2500" fromto="0 0 0 0.8165 0 0" name="SRL_geom_right_leg2" size="0.022" type="capsule"/>
						<joint armature="0.02" axis="0 1 0" damping="30" name="SRL_joint_right_kneejoint" pos="0 0 0" range="-50 50" stiffness="300"/>
						<body name="SRL_right_end" pos="0.8165 0 0" quat="0.70711 0.0 -0.70711 0.0">
							<geom density="2500" friction="5.0 0.05 0.05" name="SRL_geom_right_end" pos="0 0 -0.045" size="0.023" type="sphere"/>
							<joint armature="0.02" axis="0 1 0" damping="30" name="SRL_joint_right_ankle" pos="0 0 0" range="-5 5" stiffness="300"/>
						</body>
					</body>
				</body>
				<body name="SRL_left_leg1" pos="0.02 -0.0475 0" quat="1.0 0.0 0.0 0.0">
					<geom density="2500" fromto="0 0 0 0.3 0 0" name="SRL_geom_left_leg1" size="0.026026" type="capsule"/>
					<joint armature="0.02" axis="0 0 1" damping="30" name="SRL_joint_left_hip_z" pos="0 0 0" range="-40 0" stiffness="300"/>
					<joint armature="0.02" axis="0 1 0" damping="30" name="SRL_joint_left_hip_y" pos="0 0 0" range="-5 70" stiffness="300"/>
					<body name="SRL_left_leg2" pos="0.3 0 0" quat="0.70711 0.0 0.70711 0.0">
						<geom density="2500" fromto="0 0 0 0.8165 0 0" name="SRL_geom_left_leg2" size="0.022" type="capsule"/>
						<joint armature="0.02" axis="0 1 0" damping="30" name="SRL_joint_left_kneejoint" pos="0 0 0" range="-50 50" stiffness="300"/>
						<body name="SRL_left_end" pos="0.8165 0 0" quat="0.70711 0.0 -0.70711 0.0">
							<geom density="2500" friction="5.0 0.05 0.05" name="SRL_geom_left_end" pos="0 0 -0.045" size="0.023" type="sphere"/>
							<joint armature="0.02" axis="0 1 0" damping="30" name="SRL_joint_left_ankle" pos="0 0 0" range="-5 5" stiffness="300"/>
						</body>
					</body>
				</body>
			</body> -->

			<body name="2SRL_root" pos="-0.07 0.2 0.05" quat="0 0 0 1">
				<geom density="2500" name="2SRL_geom_root" pos="0 0 0" size="0.02 0.095 0.095" type="box"/>
				<body name="2SRL_right_leg1" pos="0.02 0.0475 0" quat="1.0 0.0 0.0 0.0">
					<geom density="2500" fromto="0 0 0 0.4 0 0" name="2SRL_geom_right_leg1" size="0.03" type="capsule"/>
					<joint armature="0.02" axis="0 0 1" damping="30" name="2SRL_joint_right_hipjoint_z" pos="0 0 0" range="0 40" stiffness="300"/>
					<joint armature="0.02" axis="0 1 0" damping="30" name="2SRL_joint_right_hipjoint_y" pos="0 0 0" range="-5 70" stiffness="300"/>
					<body name="2SRL_right_leg2" pos="0.4 0 0" quat="0.70711 0.0 0.70711 0.0">
						<geom density="2500" fromto="0 0 0 0.8 0 0" name="2SRL_geom_right_leg2" size="0.03" type="capsule"/>
						<joint armature="0.02" axis="0 1 0" damping="30" name="2SRL_joint_right_kneejoint" pos="0 0 0" range="-50 50" stiffness="300"/>
						<body name="2SRL_right_end" pos="0.8 0 0" quat="0.70711 0.0 -0.70711 0.0">
							<geom density="2500" friction="5.0 0.05 0.05" name="2SRL_geom_right_end" pos="0 0 -0.045" size="0.05" type="sphere"/>
							<joint armature="0.02" axis="0 1 0" damping="30" name="2SRL_joint_right_ankle" pos="0 0 0" range="-5 5" stiffness="300"/>
						</body>
					</body>
				</body>
				<body name="2SRL_left_leg1" pos="0.02 -0.0475 0" quat="1.0 0.0 0.0 0.0">
					<geom density="2500" fromto="0 0 0 0.4 0 0" name="2SRL_geom_left_leg1" size="0.03" type="capsule"/>
					<joint armature="0.02" axis="0 0 1" damping="30" name="2SRL_joint_left_hip_z" pos="0 0 0" range="-40 0" stiffness="300"/>
					<joint armature="0.02" axis="0 1 0" damping="30" name="2SRL_joint_left_hip_y" pos="0 0 0" range="-5 70" stiffness="300"/>
					<body name="2SRL_left_leg2" pos="0.4 0 0" quat="0.70711 0.0 0.70711 0.0">
						<geom density="2500" fromto="0 0 0 0.8 0 0" name="2SRL_geom_left_leg2" size="0.03" type="capsule"/>
						<joint armature="0.02" axis="0 1 0" damping="30" name="2SRL_joint_left_kneejoint" pos="0 0 0" range="-50 50" stiffness="300"/>
						<body name="2SRL_left_end" pos="0.8 0 0" quat="0.70711 0.0 -0.70711 0.0">
							<geom density="2500" friction="5.0 0.05 0.05" name="2SRL_geom_left_end" pos="0 0 -0.045" size="0.05" type="sphere"/>
							<joint armature="0.02" axis="0 1 0" damping="30" name="2SRL_joint_left_ankle" pos="0 0 0" range="-5 5" stiffness="300"/>
						</body>
					</body>
				</body>
			</body>
		</body>
	</worldbody>


</mujoco>