<?xml version="1.0" encoding="utf-8"?>
<mujoco model="antrobot_dfs">
	<compiler/>
	<statistic center="0 0 1" extent="2"/>
	<option gravity="0 0 0" timestep="0.00555"/>
	<size nconmax="500" njmax="1000"/>
	<custom/>
	<default>
		<motor ctrllimited="true" ctrlrange="-1 1"/>
		<default class="body">
			<geom condim="1" friction="1.0 0.05 0.05" type="capsule" solimp="0.9 0.99 0.003" solref="0.015 1"/>
			<joint armature="0.007" damping="0.1" limited="true" stiffness="5" type="hinge" solimplimit="0 0.99 0.01"/>
			<site group="3" size="0.04"/>
			<default class="force-torque">
				<site rgba="1 0 0 1" size="0.01 0.01 0.02" type="box"/>
			</default>
			<default class="touch">
				<site rgba="0 0 1 0.3" type="capsule"/>
			</default>
		</default>
	</default>
	<asset>
		<texture builtin="gradient" height="100" rgb1="1 1 1" rgb2="0 0 0" type="skybox" width="100"/>
		<texture builtin="flat" height="1278" mark="cross" markrgb="1 1 1" name="texgeom" random="0.01" rgb1="0.8 0.6 0.4" rgb2="0.8 0.6 0.4" type="cube" width="127"/>
		<texture builtin="checker" height="100" name="texplane" rgb1="0 0 0" rgb2="0.8 0.8 0.8" type="2d" width="100"/>
		<material name="MatPlane" reflectance="0.5" shininess="1" specular="1" texrepeat="60 60" texture="texplane"/>
		<material name="geom" texture="texgeom" texuniform="true"/>
	</asset>
	<worldbody>
		<light cutoff="100" diffuse="1 1 1" dir="0 0 -1.3" directional="true" exponent="1" pos="0 0 1.3" specular="0.1 0.1 0.1"/>
		<geom conaffinity="1" condim="3" material="MatPlane" name="floor" pos="0 0 0" rgba="0.8 0.9 0.8 1" size="40 40 40" type="plane"/>
		<body name="SRL_root" pos="0 0 2" quat="1.0 0.0 0.0 0.0">
			<geom name="SRL_geom_root" pos="0 0 0" size="0.25" type="sphere"/>
			<body name="SRL_leg4" pos="0 -0.25 0" quat="-0.70711 0.0 0.0 0.70711">
				<geom fromto="0 0 0 0.5 0 0" name="SRL_geom_leg4" size="0.1" type="capsule"/>
				<body name="SRL_shin4" pos="0.5 0 0" quat="0.70711 0.0 0.70711 0.0">
					<geom fromto="0 0 0 0.4 0 0" name="SRL_geom_shin4" size="0.1" type="capsule"/>
					<joint axis="0 1 0" name="SRL_joint_joint4" pos="0 0 0" range="-45 45" type="hinge"/>
				</body>
			</body>
			<body name="SRL_leg3" pos="-0.25 0 0" quat="0.0 0.0 0.0 1.0">
				<geom fromto="0 0 0 0.5 0 0" name="SRL_geom_leg3" size="0.1" type="capsule"/>
				<body name="SRL_shin3" pos="0.5 0 0" quat="0.70711 0.0 0.70711 0.0">
					<geom fromto="0 0 0 0.4 0 0" name="SRL_geom_shin3" size="0.1" type="capsule"/>
					<joint axis="0 1 0" name="SRL_joint_joint3" pos="0 0 0" range="-45 45" type="hinge"/>
				</body>
			</body>
			<body name="SRL_leg2" pos="0 0.25 0" quat="0.70711 0.0 0.0 0.70711">
				<geom fromto="0 0 0 0.5 0 0" name="SRL_geom_leg2" size="0.1" type="capsule"/>
				<body name="SRL_shin2" pos="0.5 0 0" quat="0.70711 0.0 0.70711 0.0">
					<geom fromto="0 0 0 0.4 0 0" name="SRL_geom_shin2" size="0.1" type="capsule"/>
					<joint axis="0 1 0" name="SRL_joint_joint2" pos="0 0 0" range="-45 45" type="hinge"/>
				</body>
			</body>
			<body name="SRL_leg1" pos="0.25 0 0" quat="1.0 0.0 0.0 0.0">
				<geom fromto="0 0 0 0.5 0 0" name="SRL_geom_leg1" size="0.1" type="capsule"/>
				<joint axis="0 0 1" name="SRL_joint_joint01" pos="0 0 0" range="-45 45" type="hinge"/>
				<joint axis="0 1 0" name="SRL_joint_joint02" pos="0 0 0" range="-45 45" type="hinge"/>
				<body name="SRL_shin1" pos="0.5 0 0" quat="0.70711 0.0 0.70711 0.0">
					<geom fromto="0 0 0 0.4 0 0" name="SRL_geom_shin1" size="0.1" type="capsule"/>
					<joint axis="0 1 0" name="SRL_joint_joint1" pos="0 0 0" range="-45 45" type="hinge"/>
				</body>
			</body>
		</body>
	</worldbody>
	<actuator>
		<motor ctrllimited="true" ctrlrange="-1 1" joint="SRL_joint_joint4"/>
		<motor ctrllimited="true" ctrlrange="-1 1" joint="SRL_joint_joint3"/>
		<motor ctrllimited="true" ctrlrange="-1 1" joint="SRL_joint_joint2"/>
		<motor ctrllimited="true" ctrlrange="-1 1" joint="SRL_joint_joint01"/>
		<motor ctrllimited="true" ctrlrange="-1 1" joint="SRL_joint_joint02"/>
		<motor ctrllimited="true" ctrlrange="-1 1" joint="SRL_joint_joint1"/>
	</actuator>
</mujoco>