<?xml version="1.0" encoding="utf-8"?>
<mujoco model="srl_4">
	<compiler/>
	<option gravity="0 0 0"/>
	<size nconmax="500" njmax="1000"/>
	<custom/>
	<default>
		<joint armature="1" damping="1" limited="true"/>
		<geom conaffinity="0" condim="3" margin="0.01" rgba="0.8 0.6 0.4 1"/>
	</default>
	<asset>
		<texture builtin="gradient" height="100" rgb1="1 1 1" rgb2="0 0 0" type="skybox" width="100"/>
		<texture builtin="flat" height="1278" mark="cross" markrgb="1 1 1" name="texgeom" random="0.01" rgb1="0.8 0.6 0.4" rgb2="0.8 0.6 0.4" type="cube" width="127"/>
		<texture builtin="checker" height="100" name="texplane" rgb1="0 0 0" rgb2="0.8 0.8 0.8" type="2d" width="100"/>
		<material name="MatPlane" reflectance="0.5" shininess="1" specular="1" texrepeat="60 60" texture="texplane"/>
		<material name="geom" texture="texgeom" texuniform="true"/>
		<material name="SRL" rgba="0.66 0.65 0.68 1"/>
	</asset>
	<worldbody>
		<light cutoff="100" diffuse="1 1 1" dir="0 0 -1.3" directional="true" exponent="1" pos="0 0 1.3" specular="0.1 0.1 0.1"/>
		<geom conaffinity="1" condim="3" material="MatPlane" name="floor" pos="0 0 0" rgba="0.8 0.9 0.8 1" size="40 40 40" type="plane"/>
		<body name="SRL_root" pos="0 0 2" quat="0.0 0.0 0.0 1.0">
			<geom material="SRL" name="SRL_geom_root" pos="0 0 0" size="0.02 0.095 0.095" type="box"/>
			<body name="SRL_leg2" pos="0.02 0.0475 0" quat="1.0 0.0 0.0 0.0">
				<geom fromto="0 0 0 0.1 0 0" material="SRL" name="SRL_geom_leg2" size="0.03" type="capsule"/>
				<joint axis="0 0 1" name="SRL_joint_joint11" pos="0 0 0" range="-45 45" type="hinge"/>
				<joint axis="0 1 0" name="SRL_joint_joint12" pos="0 0 0" range="-45 45" type="hinge"/>
				<body name="SRL_shin11" pos="0.1 0 0" quat="0.92388 0.0 0.38268 0.0">
					<geom fromto="0 0 0 0.8 0 0" material="SRL" name="SRL_geom_shin11" size="0.03" type="capsule"/>
					<joint axis="0 1 0" name="SRL_joint_joint13" pos="0 0 0" range="-45 45" type="hinge"/>
					<body name="SRL_shin12" pos="0.8 0 0" quat="0.70711 0.0 -0.70711 0.0">
						<geom fromto="0 0 0 0.18 0 0" material="SRL" name="SRL_geom_shin12" size="0.03" type="capsule"/>
						<joint axis="0 1 0" name="SRL_joint_joint14" pos="0 0 0" range="-45 45" type="hinge"/>
					</body>
				</body>
			</body>
			<body name="SRL_leg1" pos="0.02 -0.0475 0" quat="1.0 0.0 0.0 0.0">
				<geom fromto="0 0 0 0.1 0 0" material="SRL" name="SRL_geom_leg1" size="0.03" type="capsule"/>
				<joint axis="0 0 1" name="SRL_joint_joint01" pos="0 0 0" range="-45 45" type="hinge"/>
				<joint axis="0 1 0" name="SRL_joint_joint02" pos="0 0 0" range="-45 45" type="hinge"/>
				<body name="SRL_shin1" pos="0.1 0 0" quat="0.92388 0.0 0.38268 0.0">
					<geom fromto="0 0 0 0.8 0 0" material="SRL" name="SRL_geom_shin1" size="0.03" type="capsule"/>
					<joint axis="0 1 0" name="SRL_joint_joint1" pos="0 0 0" range="-45 45" type="hinge"/>
					<body name="SRL_shin2" pos="0.8 0 0" quat="0.70711 0.0 -0.70711 0.0">
						<geom fromto="0 0 0 0.18 0 0" material="SRL" name="SRL_geom_shin2" size="0.03" type="capsule"/>
						<joint axis="0 1 0" name="SRL_joint_joint2" pos="0 0 0" range="-45 45" type="hinge"/>
					</body>
				</body>
			</body>
		</body>
	</worldbody>
	<actuator>
		<motor ctrllimited="true" ctrlrange="-1 1" joint="SRL_joint_joint11"/>
		<motor ctrllimited="true" ctrlrange="-1 1" joint="SRL_joint_joint12"/>
		<motor ctrllimited="true" ctrlrange="-1 1" joint="SRL_joint_joint13"/>
		<motor ctrllimited="true" ctrlrange="-1 1" joint="SRL_joint_joint14"/>
		<motor ctrllimited="true" ctrlrange="-1 1" joint="SRL_joint_joint01"/>
		<motor ctrllimited="true" ctrlrange="-1 1" joint="SRL_joint_joint02"/>
		<motor ctrllimited="true" ctrlrange="-1 1" joint="SRL_joint_joint1"/>
		<motor ctrllimited="true" ctrlrange="-1 1" joint="SRL_joint_joint2"/>
	</actuator>
</mujoco>