<?xml version="1.0" encoding="utf-8"?>
<!-- 单独训练外肢体 -->
<mujoco model="XMLModel">
	<statistic center="0 0 1" extent="2"/>
	<option timestep="0.00555"/>
	<default>
		<motor ctrllimited="true" ctrlrange="-1 1"/>
		<default class="body">
			<geom condim="1" friction="1.0 0.05 0.05" type="capsule" solimp="0.9 0.99 0.003" solref="0.015 1"/>
			<joint armature="0.007" damping="0.1" limited="true" stiffness="5" type="hinge" solimplimit="0 0.99 0.01"/>
			<site group="3" size="0.04"/>
			<default class="force-torque">
				<site rgba="1 0 0 1" size="0.01 0.01 0.02" type="box"/>
			</default>
			<default class="touch">
				<site rgba="0 0 1 0.3" type="capsule"/>
			</default>
		</default>
	</default>
	<asset/>
	<worldbody>
		<geom conaffinity="1" name="floor" size="100 100 0.2" type="plane"/>
			<body childclass="body" name="SRL" pos="0 0 1">
                <freejoint name="root"/>
                <!-- <geom name="board" pos="0 0 0" size="0.0005 0.1 0.1 " type="box" density='100'/>  -->
				<body name="SRL_root" pos="-0.25 0 0" quat="0.0 0.0 0.0 1.0">
                    <!-- <joint armature="0.02" axis="0 1 0" damping="0" name="SRL_freejoint_y" pos="-0.525 0 0" range="-45 45" stiffness="0"/> -->
					<geom density="1000" name="SRL_geom_root" pos="0 0 0" size="0.2 0.095 0.05" type="box" contype="1" conaffinity="1"/>
					<!-- <geom density="1000" name="SRL_geom_load" pos="0 0 0.35" size="0.13 0.13 0.22" type="box" contype="1" conaffinity="1"/> -->
					<geom density="2000" name="SRL_geom_load" pos="0 0 0.22" size="0.13 0.13 0.11" type="box" contype="1" conaffinity="1"/>
					<body name="SRL_right_leg1" pos="0.02 0.13 0"  quat="1.0 0.0 0.0 0.0">
						<geom density="1000" fromto="0 0 0 0.60 0 0" name="SRL_geom_right_leg1" size="0.03" type="capsule"/>
						<joint armature="0.02" axis="0 0 1" damping="30" name="SRL_joint_right_hipjoint_z" pos="0 0 0" range="0 40" stiffness="300"/>
						<joint armature="0.02" axis="0 1 0" damping="30" name="SRL_joint_right_hipjoint_y" pos="0 0 0" range="-5 70" stiffness="300"/>
						<body name="SRL_right_leg2" pos="0.60 0 0" quat="0.92388 0.0 0.38268 0.0">
							<geom density="1000" fromto="0 0 0 0.50 0 0" name="SRL_geom_right_leg2" size="0.03" type="capsule"/>
							<joint armature="0.02" axis="0 1 0" damping="30" name="SRL_joint_right_kneejoint" pos="0 0 0" range="-50 50" stiffness="300"/>
							<body name="SRL_right_end" pos="0.50 0 0" quat="0.70711 0.0 -0.70711 0.0">
								<geom density="1000" friction="5.0 0.05 0.05" name="SRL_geom_right_end" pos="0 0 -0.045" size="0.05" type="sphere" collision="true" contype="1" conaffinity="1"/>
								<!-- <joint armature="0.02" axis="0 1 0" damping="30" name="SRL_joint_right_ankle" pos="0 0 0" range="-5 5" stiffness="300"/> -->
							</body>
						</body>
					</body>
					<body name="SRL_left_leg1" pos="0.02 -0.13 0"  quat="1.0 0.0 0.0 0.0">
						<geom density="1000" fromto="0 0 0 0.60 0 0" name="SRL_geom_left_leg1" size="0.03" type="capsule"/>
						<joint armature="0.02" axis="0 0 -1" damping="30" name="SRL_joint_left_hip_z" pos="0 0 0" range="0 40" stiffness="300"/>
						<joint armature="0.02" axis="0 1 0" damping="30" name="SRL_joint_left_hip_y" pos="0 0 0" range="-5 70" stiffness="300"/>
						<body name="SRL_left_leg2" pos="0.60 0 0" quat="0.92388 0.0 0.38268 0.0">
							<geom density="1000" fromto="0 0 0 0.50 0 0" name="SRL_geom_left_leg2" size="0.03" type="capsule"/>
							<joint armature="0.02" axis="0 1 0" damping="30" name="SRL_joint_left_kneejoint" pos="0 0 0" range="-50 50" stiffness="300"/>
							<body name="SRL_left_end" pos="0.50 0 0" quat="0.70711 0.0 -0.70711 0.0">
								<geom density="1000" friction="5.0 0.05 0.05" name="SRL_geom_left_end" pos="0 0 -0.045" size="0.05" type="sphere" collision="true"/>
								<!-- <joint armature="0.02" axis="0 1 0" damping="30" name="SRL_joint_left_ankle" pos="0 0 0" range="-5 5" stiffness="300"/> -->
							</body>
						</body>
					</body>
				</body>
			</body>
	</worldbody>
	<actuator>
		<motor gear="125" joint="SRL_joint_right_hipjoint_z" name="SRL_joint_right_hipjoint_z"/>
		<motor gear="125" joint="SRL_joint_right_hipjoint_y" name="SRL_joint_right_hipjoint_y"/>
		<motor gear="125" joint="SRL_joint_right_kneejoint" name="SRL_joint_right_kneejoint"/>
		<motor gear="125" joint="SRL_joint_right_ankle" name="SRL_joint_right_ankle"/>
		<motor gear="125" joint="SRL_joint_left_hip_z" name="SRL_joint_left_hip_z"/>
		<motor gear="125" joint="SRL_joint_left_hip_y" name="SRL_joint_left_hip_y"/>
		<motor gear="125" joint="SRL_joint_left_kneejoint" name="SRL_joint_left_kneejoint"/>
		<motor gear="125" joint="SRL_joint_left_ankle" name="SRL_joint_left_ankle"/>
	</actuator>
	<sensor>
		<subtreelinvel body="pelvis" name="pelvis_subtreelinvel"/>
		<accelerometer site="root" name="root_accel"/>
		<velocimeter site="root" name="root_vel"/>
		<gyro site="root" name="root_gyro"/>
		<force site="left_ankle" name="left_ankle_force"/>
		<force site="right_ankle" name="right_ankle_force"/>
		<force site="left_knee" name="left_knee_force"/>
		<force site="right_knee" name="right_knee_force"/>
		<force site="left_hip" name="left_hip_force"/>
		<force site="right_hip" name="right_hip_force"/>
		<torque site="left_ankle" name="left_ankle_torque"/>
		<torque site="right_ankle" name="right_ankle_torque"/>
		<torque site="left_knee" name="left_knee_torque"/>
		<torque site="right_knee" name="right_knee_torque"/>
		<torque site="left_hip" name="left_hip_torque"/>
		<torque site="right_hip" name="right_hip_torque"/>
		<touch site="pelvis" name="pelvis_touch"/>
		<touch site="upper_waist" name="upper_waist_touch"/>
		<touch site="torso" name="torso_touch"/>
		<touch site="head" name="head_touch"/>
		<touch site="right_upper_arm" name="right_upper_arm_touch"/>
		<touch site="right_lower_arm" name="right_lower_arm_touch"/>
		<touch site="right_hand" name="right_hand_touch"/>
		<touch site="left_upper_arm" name="left_upper_arm_touch"/>
		<touch site="left_lower_arm" name="left_lower_arm_touch"/>
		<touch site="left_hand" name="left_hand_touch"/>
		<touch site="right_thigh" name="right_thigh_touch"/>
		<touch site="right_shin" name="right_shin_touch"/>
		<touch site="right_foot" name="right_foot_touch"/>
		<touch site="left_thigh" name="left_thigh_touch"/>
		<touch site="left_shin" name="left_shin_touch"/>
		<touch site="left_foot" name="left_foot_touch"/>
	</sensor>
</mujoco>